Workbook

Sheet Personal Expenditure
B2: Personal Survival Budget
B4: Name: | D4: tracie walker
B6: Business Name: | D6: conscious candles n mindful melts
B8: Date: | D8: 44520
B11: Personal Income | D11: Monthly Income | G11: Personal Expenditure | I11: Monthly Expenditure
B13: Employed Income | G13: Rent/Mortgage | I13: 280
B14: Partner's Income | G14: Council Tax | I14: 200
B15: Pension | G15: Utilities | I15: 60
B16: Lodgers | G16: TV Licence | I16: 10
B17: Maintenance | G17: Phone/Internet | I17: 29
B18: DLA/PIP | D18: 240 | G18: TV Packages
B19: Carers Allowance | G19: Insurances | I19: 10
B20: Child Benefit | E20: =SUM(D13:D20) -> 240
G21: Travel Expenses
B22: Universal Credit | D22: 700 | G22: Car Tax and Insurance
B23: Tax Credits
B24: Housing Benefit | D24: 280 | G24: Groceries | I24: 150
B25: Council tax benefit | D25: 200 | E25: =SUM(D22:D25) -> 1180 | G25: School/Work Dinners
G26: Clothing
B27: Job Seekers Allowance | G27: Leisure and Hobbies | I27: 50
B28: Income Support | G28: Pocketmoney
G29: Pet Bills
B30: Any other income | G30: Child/adult care costs
G32: Secured Loan
G33: Unsecured Loans
G34: Catalogues/Cards
G36: Any other expenses | I36: 50
B38: TOTALS | D38: =SUM(D13:D34) -> 1420 | G38: TOTALS | I38: =SUM(I13:I36) -> 839
B41: Any notes (IE. Savings/Live with parents)

Sheet Sales Forecast
B2: Monthly Sales Forecast | D2: Name: | F2: tracie walker
D4: Business Name: | F4: conscious candles n mindful melts
D6: Date: | F6: 44520
B8: Year 1
D9: Month | E9: Dec | F9: Jan | G9: Feb | H9: Mar | I9: Apr | J9: May | K9: Jun | L9: Jul | M9: Aug | N9: Sep | O9: Oct | P9: Nov
B10: Product/Service | C10: Sales Price/Day Rate | D10: Direct Costs | E10: M 1 | F10: M 2 | G10: M 3 | H10: M 4 | I10: M 5 | J10: M 6 | K10: M 7 | L10: M 8 | M10: M 9 | N10: M 10 | O10: M 11 | P10: M 12 | Q10: Numbers | R10: Income | S10: Cost | T10: Gross Profit | U10: GP%
B11: rec tealights | C11: 20 | D11: 10 | E11: 10 | F11: 5 | G11: 10 | H11: 7 | I11: 7 | J11: 10 | K11: 10 | L11: 10 | M11: 10 | N11: 10 | O11: 10 | P11: 10 | Q11: =SUM(E11:P11) -> 109 | R11: =SUM(Q11*C11) -> 2180 | S11: =SUM(Q11*D11) -> 1090 | T11: =SUM(R11-S11) -> 1090 | U11: =IF(T11=0,"",SUM(T11/R11)) -> 0.5
B12: rec tealights direct | C12: 5 | D12: 1 | E12: 5 | F12: 4 | G12: 4 | H12: 4 | I12: 5 | J12: 5 | K12: 5 | L12: 5 | M12: 6 | N12: 6 | O12: 6 | P12: 6 | Q12: =SUM(E12:P12) -> 61 | R12: =SUM(Q12*C12) -> 305 | S12: =SUM(Q12*D12) -> 61 | T12: =SUM(R12-S12) -> 244 | U12: =IF(T12=0,"",SUM(T12/R12)) -> 0.8
B13: melts trade kg | C13: 40 | D13: 14.35 | E13: 10 | F13: 5 | G13: 10 | H13: 6 | I13: 7 | J13: 7 | K13: 8 | L13: 8 | M13: 8 | N13: 8 | O13: 8 | P13: 10 | Q13: =SUM(E13:P13) -> 95 | R13: =SUM(Q13*C13) -> 3800 | S13: =SUM(Q13*D13) -> 1363.25 | T13: =SUM(R13-S13) -> 2436.75 | U13: =IF(T13=0,"",SUM(T13/R13)) -> 0.64125
B14: rec jars direct | C14: 6.5 | D14: 1.73 | E14: 10 | F14: 5 | G14: 10 | H14: 6 | I14: 7 | J14: 7 | K14: 8 | L14: 8 | M14: 9 | N14: 9 | O14: 10 | P14: 10 | Q14: =SUM(E14:P14) -> 99 | R14: =SUM(Q14*C14) -> 643.5 | S14: =SUM(Q14*D14) -> 171.27 | T14: =SUM(R14-S14) -> 472.23 | U14: =IF(T14=0,"",SUM(T14/R14)) -> 0.73384615
B15: rec jars trade | C15: 50 | D15: 14.6 | E15: 5 | F15: 2 | G15: 2 | H15: 2 | I15: 3 | J15: 3 | K15: 3 | L15: 3 | M15: 4 | N15: 4 | O15: 5 | P15: 5 | Q15: =SUM(E15:P15) -> 41 | R15: =SUM(Q15*C15) -> 2050 | S15: =SUM(Q15*D15) -> 598.6 | T15: =SUM(R15-S15) -> 1451.4 | U15: =IF(T15=0,"",SUM(T15/R15)) -> 0.708
B16: 50g melts direct | C16: 3 | D16: 0.71 | E16: 20 | F16: 5 | G16: 5 | H16: 6 | I16: 5 | J16: 6 | K16: 6 | L16: 8 | M16: 9 | N16: 9 | O16: 10 | P16: 10 | Q16: =SUM(E16:P16) -> 99 | R16: =SUM(Q16*C16) -> 297 | S16: =SUM(Q16*D16) -> 70.29 | T16: =SUM(R16-S16) -> 226.71 | U16: =IF(T16=0,"",SUM(T16/R16)) -> 0.76333333
B17: markets | C17: 50 | D17: 30 | E17: 9 | F17: 5 | G17: 5 | H17: 9 | I17: 9 | J17: 9 | K17: 9 | L17: 9 | M17: 9 | N17: 9 | O17: 6 | P17: 6 | Q17: =SUM(E17:P17) -> 94 | R17: =SUM(Q17*C17) -> 4700 | S17: =SUM(Q17*D17) -> 2820 | T17: =SUM(R17-S17) -> 1880 | U17: =IF(T17=0,"",SUM(T17/R17)) -> 0.4
Q18: =SUM(E18:P18) -> 0 | R18: =SUM(Q18*C18) -> 0 | S18: =SUM(Q18*D18) -> 0 | T18: =SUM(R18-S18) -> 0 | U18: =IF(T18=0,"",SUM(T18/R18))
Q19: =SUM(E19:P19) -> 0 | R19: =SUM(Q19*C19) -> 0 | S19: =SUM(Q19*D19) -> 0 | T19: =SUM(R19-S19) -> 0 | U19: =IF(T19=0,"",SUM(T19/R19))
Q20: =SUM(E20:P20) -> 0 | R20: =SUM(Q20*C20) -> 0 | S20: =SUM(Q20*D20) -> 0 | T20: =SUM(R20-S20) -> 0 | U20: =IF(T20=0,"",SUM(T20/R20))
E21: =SUM(E11:E20) -> 69 | F21: =SUM(F11:F20) -> 31 | G21: =SUM(G11:G20) -> 46 | H21: =SUM(H11:H20) -> 40 | I21: =SUM(I11:I20) -> 43 | J21: =SUM(J11:J20) -> 47 | K21: =SUM(K11:K20) -> 49 | L21: =SUM(L11:L20) -> 51 | ... T21: =SUM(T11:T20) -> 7801.09 | U21: =IF(T21=0,"",SUM(T21/R21)) -> 0.55819756
B22: Income per month to CFF | E22: =SUM(E11*$C11)+(E16*$C16)+(E17*$C17)+(E18*$C18)+(E19*$C19)+(E20*$C20)+(E12*$C12)+(E13*$C13)+(E14*$C14)+(E15*$C15) -> 1450 | F22: =SUM(F11*$C11)+(F16*$C16)+(F17*$C17)+(F18*$C18)+(F19*$C19)+(F20*$C20)+(F12*$C12)+(F13*$C13)+(F14*$C14)+(F15*$C15) -> 717.5 | G22: =SUM(G11*$C11)+(G16*$C16)+(G17*$C17)+(G18*$C18)+(G19*$C19)+(G20*$C20)+(G12*$C12)+(G13*$C13)+(G14*$C14)+(G15*$C15) -> 1050 | H22: =SUM(H11*$C11)+(H16*$C16)+(H17*$C17)+(H18*$C18)+(H19*$C19)+(H20*$C20)+(H12*$C12)+(H13*$C13)+(H14*$C14)+(H15*$C15) -> 1007 | I22: =SUM(I11*$C11)+(I16*$C16)+(I17*$C17)+(I18*$C18)+(I19*$C19)+(I20*$C20)+(I12*$C12)+(I13*$C13)+(I14*$C14)+(I15*$C15) -> 1105.5 | J22: =SUM(J11*$C11)+(J16*$C16)+(J17*$C17)+(J18*$C18)+(J19*$C19)+(J20*$C20)+(J12*$C12)+(J13*$C13)+(J14*$C14)+(J15*$C15) -> 1168.5 | K22: =SUM(K11*$C11)+(K16*$C16)+(K17*$C17)+(K18*$C18)+(K19*$C19)+(K20*$C20)+(K12*$C12)+(K13*$C13)+(K14*$C14)+(K15*$C15) -> 1215 | L22: =SUM(L11*$C11)+(L16*$C16)+(L17*$C17)+(L18*$C18)+(L19*$C19)+(L20*$C20)+(L12*$C12)+(L13*$C13)+(L14*$C14)+(L15*$C15) -> 1221 | ... P22: =SUM(P11*$C11)+(P16*$C16)+(P17*$C17)+(P18*$C18)+(P19*$C19)+(P20*$C20)+(P12*$C12)+(P13*$C13)+(P14*$C14)+(P15*$C15) -> 1275 | Q22: =SUM(E22:P22) -> 13975.5
B23: Cost per month to CFF (direct costs) | E23: =SUM(E12*$D12)+(E17*$D17)+(E18*$D18)+(E19*$D19)+(E20*$D20)+(E11*$D11)+(E13*$D13)+(E14*$D14)+(E15*$D15)+(E16*$D16) -> 623 | F23: =SUM(F12*$D12)+(F17*$D17)+(F18*$D18)+(F19*$D19)+(F20*$D20)+(F11*$D11)+(F13*$D13)+(F14*$D14)+(F15*$D15)+(F16*$D16) -> 317.15 | G23: =SUM(G12*$D12)+(G17*$D17)+(G18*$D18)+(G19*$D19)+(G20*$D20)+(G11*$D11)+(G13*$D13)+(G14*$D14)+(G15*$D15)+(G16*$D16) -> 447.55 | H23: =SUM(H12*$D12)+(H17*$D17)+(H18*$D18)+(H19*$D19)+(H20*$D20)+(H11*$D11)+(H13*$D13)+(H14*$D14)+(H15*$D15)+(H16*$D16) -> 473.94 | I23: =SUM(I12*$D12)+(I17*$D17)+(I18*$D18)+(I19*$D19)+(I20*$D20)+(I11*$D11)+(I13*$D13)+(I14*$D14)+(I15*$D15)+(I16*$D16) -> 504.91 | J23: =SUM(J12*$D12)+(J17*$D17)+(J18*$D18)+(J19*$D19)+(J20*$D20)+(J11*$D11)+(J13*$D13)+(J14*$D14)+(J15*$D15)+(J16*$D16) -> 535.62 | K23: =SUM(K12*$D12)+(K17*$D17)+(K18*$D18)+(K19*$D19)+(K20*$D20)+(K11*$D11)+(K13*$D13)+(K14*$D14)+(K15*$D15)+(K16*$D16) -> 551.7 | L23: =SUM(L12*$D12)+(L17*$D17)+(L18*$D18)+(L19*$D19)+(L20*$D20)+(L11*$D11)+(L13*$D13)+(L14*$D14)+(L15*$D15)+(L16*$D16) -> 553.12 | ... P23: =SUM(P12*$D12)+(P17*$D17)+(P18*$D18)+(P19*$D19)+(P20*$D20)+(P11*$D11)+(P13*$D13)+(P14*$D14)+(P15*$D15)+(P16*$D16) -> 526.9 | Q23: =SUM(E23:P23) -> 6174.41
B25: Year 2
B26: NB: Only required for loans over £2,500
D27: Month
B28: Product/Service | C28: Sales Price/Day Rate | D28: Direct Costs | E28: M 13 | F28: M 14 | G28: M 15 | H28: M 16 | I28: M 17 | J28: M 18 | K28: M 19 | L28: M 20 | M28: M 21 | N28: M 22 | O28: M 23 | P28: M 24 | Q28: Numbers | R28: Income | S28: Cost | T28: Gross Profit | U28: GP%
Q29: =SUM(E29:P29) -> 0 | R29: =SUM(Q29*C29) -> 0 | S29: =SUM(Q29*D29) -> 0 | T29: =SUM(R29-S29) -> 0 | U29: =IF(T29=0,"",SUM(T29/R29))
Q30: =SUM(E30:P30) -> 0 | R30: =SUM(Q30*C30) -> 0 | S30: =SUM(Q30*D30) -> 0 | T30: =SUM(R30-S30) -> 0 | U30: =IF(T30=0,"",SUM(T30/R30))
Q31: =SUM(E31:P31) -> 0 | R31: =SUM(Q31*C31) -> 0 | S31: =SUM(Q31*D31) -> 0 | T31: =SUM(R31-S31) -> 0 | U31: =IF(T31=0,"",SUM(T31/R31))
Q32: =SUM(E32:P32) -> 0 | R32: =SUM(Q32*C32) -> 0 | S32: =SUM(Q32*D32) -> 0 | T32: =SUM(R32-S32) -> 0 | U32: =IF(T32=0,"",SUM(T32/R32))
Q33: =SUM(E33:P33) -> 0 | R33: =SUM(Q33*C33) -> 0 | S33: =SUM(Q33*D33) -> 0 | T33: =SUM(R33-S33) -> 0 | U33: =IF(T33=0,"",SUM(T33/R33))
Q34: =SUM(E34:P34) -> 0 | R34: =SUM(Q34*C34) -> 0 | S34: =SUM(Q34*D34) -> 0 | T34: =SUM(R34-S34) -> 0 | U34: =IF(T34=0,"",SUM(T34/R34))
Q35: =SUM(E35:P35) -> 0 | R35: =SUM(Q35*C35) -> 0 | S35: =SUM(Q35*D35) -> 0 | T35: =SUM(R35-S35) -> 0 | U35: =IF(T35=0,"",SUM(T35/R35))
Q36: =SUM(E36:P36) -> 0 | R36: =SUM(Q36*C36) -> 0 | S36: =SUM(Q36*D36) -> 0 | T36: =SUM(R36-S36) -> 0 | U36: =IF(T36=0,"",SUM(T36/R36))
Q37: =SUM(E37:P37) -> 0 | R37: =SUM(Q37*C37) -> 0 | S37: =SUM(Q37*D37) -> 0 | T37: =SUM(R37-S37) -> 0 | U37: =IF(T37=0,"",SUM(T37/R37))
Q38: =SUM(E38:P38) -> 0 | R38: =SUM(Q38*C38) -> 0 | S38: =SUM(Q38*D38) -> 0 | T38: =SUM(R38-S38) -> 0 | U38: =IF(T38=0,"",SUM(T38/R38))
E39: =SUM(E29:E38) -> 0 | F39: =SUM(F29:F38) -> 0 | G39: =SUM(G29:G38) -> 0 | H39: =SUM(H29:H38) -> 0 | I39: =SUM(I29:I38) -> 0 | J39: =SUM(J29:J38) -> 0 | K39: =SUM(K29:K38) -> 0 | L39: =SUM(L29:L38) -> 0 | ... T39: =SUM(T29:T38) -> 0 | U39: =IF(T39=0,"",SUM(T39/R39))
B40: Income per month to CFF | E40: =SUM(E29*$C29)+(E34*$C34)+(E35*$C35)+(E36*$C36)+(E37*$C37)+(E38*$C38)+(E30*$C30)+(E31*$C31)+(E32*$C32)+(E33*$C33) -> 0 | F40: =SUM(F29*$C29)+(F34*$C34)+(F35*$C35)+(F36*$C36)+(F37*$C37)+(F38*$C38)+(F30*$C30)+(F31*$C31)+(F32*$C32)+(F33*$C33) -> 0 | G40: =SUM(G29*$C29)+(G34*$C34)+(G35*$C35)+(G36*$C36)+(G37*$C37)+(G38*$C38)+(G30*$C30)+(G31*$C31)+(G32*$C32)+(G33*$C33) -> 0 | H40: =SUM(H29*$C29)+(H34*$C34)+(H35*$C35)+(H36*$C36)+(H37*$C37)+(H38*$C38)+(H30*$C30)+(H31*$C31)+(H32*$C32)+(H33*$C33) -> 0 | I40: =SUM(I29*$C29)+(I34*$C34)+(I35*$C35)+(I36*$C36)+(I37*$C37)+(I38*$C38)+(I30*$C30)+(I31*$C31)+(I32*$C32)+(I33*$C33) -> 0 | J40: =SUM(J29*$C29)+(J34*$C34)+(J35*$C35)+(J36*$C36)+(J37*$C37)+(J38*$C38)+(J30*$C30)+(J31*$C31)+(J32*$C32)+(J33*$C33) -> 0 | K40: =SUM(K29*$C29)+(K34*$C34)+(K35*$C35)+(K36*$C36)+(K37*$C37)+(K38*$C38)+(K30*$C30)+(K31*$C31)+(K32*$C32)+(K33*$C33) -> 0 | L40: =SUM(L29*$C29)+(L34*$C34)+(L35*$C35)+(L36*$C36)+(L37*$C37)+(L38*$C38)+(L30*$C30)+(L31*$C31)+(L32*$C32)+(L33*$C33) -> 0 | ... P40: =SUM(P29*$C29)+(P34*$C34)+(P35*$C35)+(P36*$C36)+(P37*$C37)+(P38*$C38)+(P30*$C30)+(P31*$C31)+(P32*$C32)+(P33*$C33) -> 0 | Q40: =SUM(E40:P40) -> 0
B41: Cost per month to CFF (direct costs) | E41: =SUM(E30*$D30)+(E35*$D35)+(E36*$D36)+(E37*$D37)+(E38*$D38)+(E29*$D29)+(E31*$D31)+(E32*$D32)+(E33*$D33)+(E34*$D34) -> 0 | F41: =SUM(F30*$D30)+(F35*$D35)+(F36*$D36)+(F37*$D37)+(F38*$D38)+(F29*$D29)+(F31*$D31)+(F32*$D32)+(F33*$D33)+(F34*$D34) -> 0 | G41: =SUM(G30*$D30)+(G35*$D35)+(G36*$D36)+(G37*$D37)+(G38*$D38)+(G29*$D29)+(G31*$D31)+(G32*$D32)+(G33*$D33)+(G34*$D34) -> 0 | H41: =SUM(H30*$D30)+(H35*$D35)+(H36*$D36)+(H37*$D37)+(H38*$D38)+(H29*$D29)+(H31*$D31)+(H32*$D32)+(H33*$D33)+(H34*$D34) -> 0 | I41: =SUM(I30*$D30)+(I35*$D35)+(I36*$D36)+(I37*$D37)+(I38*$D38)+(I29*$D29)+(I31*$D31)+(I32*$D32)+(I33*$D33)+(I34*$D34) -> 0 | J41: =SUM(J30*$D30)+(J35*$D35)+(J36*$D36)+(J37*$D37)+(J38*$D38)+(J29*$D29)+(J31*$D31)+(J32*$D32)+(J33*$D33)+(J34*$D34) -> 0 | K41: =SUM(K30*$D30)+(K35*$D35)+(K36*$D36)+(K37*$D37)+(K38*$D38)+(K29*$D29)+(K31*$D31)+(K32*$D32)+(K33*$D33)+(K34*$D34) -> 0 | L41: =SUM(L30*$D30)+(L35*$D35)+(L36*$D36)+(L37*$D37)+(L38*$D38)+(L29*$D29)+(L31*$D31)+(L32*$D32)+(L33*$D33)+(L34*$D34) -> 0 | ... P41: =SUM(P30*$D30)+(P35*$D35)+(P36*$D36)+(P37*$D37)+(P38*$D38)+(P29*$D29)+(P31*$D31)+(P32*$D32)+(P33*$D33)+(P34*$D34) -> 0 | Q41: =SUM(E41:P41) -> 0

Sheet Cash Flow Forecast Yr1
B2: Cash flow Forecast | E2: Name: | G2: tracie walker
E4: Business Name: | G4: conscious candles n mindful melts
E6: Date: | G6: 44520
C7: Put anything spent on the business prior to opening in this column
B8: Year 1 | D8: Dec | E8: Jan | F8: Feb | G8: Mar | H8: Apr | I8: May | J8: Jun | K8: Jul | L8: Aug | M8: Sep | N8: Oct | O8: Nov
C9: Pre-Start | D9: M 1 | E9: M 2 | F9: M 3 | G9: M 4 | H9: M 5 | I9: M 6 | J9: M 7 | K9: M 8 | L9: M 9 | M9: M 10 | N9: M 11 | O9: M 12 | P9: Totals | Q9: P&L
B10: Sales | D10: ='Sales Forecast'!E22 -> 1450 | E10: ='Sales Forecast'!F22 -> 717.5 | F10: ='Sales Forecast'!G22 -> 1050 | G10: ='Sales Forecast'!H22 -> 1007 | H10: ='Sales Forecast'!I22 -> 1105.5 | I10: ='Sales Forecast'!J22 -> 1168.5 | J10: ='Sales Forecast'!K22 -> 1215 | K10: ='Sales Forecast'!L22 -> 1221 | ... O10: ='Sales Forecast'!P22 -> 1275 | P10: =SUM(C10:O10) -> 13975.5 | Q10: =P10 -> 13975.5
B11: Own Cash/Grants | P11: =SUM(C11:O11) -> 0 | Q11: =P11 -> 0
B12: Loans | C12: 2500 | P12: =SUM(C12:O12) -> 2500 | Q12: =P12 -> 2500
B13: Total Income | C13: =SUM(C10:C12) -> 2500 | D13: =SUM(D10:D12) -> 1450 | E13: =SUM(E10:E12) -> 717.5 | F13: =SUM(F10:F12) -> 1050 | G13: =SUM(G10:G12) -> 1007 | H13: =SUM(H10:H12) -> 1105.5 | I13: =SUM(I10:I12) -> 1168.5 | J13: =SUM(J10:J12) -> 1215 | ... Q13: =SUM(Q10:Q12) -> 16475.5
B14: Direct Costs | C14: 300 | D14: ='Sales Forecast'!E23 -> 623 | E14: ='Sales Forecast'!F23 -> 317.15 | F14: ='Sales Forecast'!G23 -> 447.55 | G14: ='Sales Forecast'!H23 -> 473.94 | H14: ='Sales Forecast'!I23 -> 504.91 | I14: ='Sales Forecast'!J23 -> 535.62 | J14: ='Sales Forecast'!K23 -> 551.7 | K14: ='Sales Forecast'!L23 -> 553.12 | ... O14: ='Sales Forecast'!P23 -> 526.9 | P14: =+SUM(C14:O14) -> 6474.41 | Q14: =P14 -> 6474.41
B15: Rent & Rates | P15: =+SUM(C15:O15) -> 0 | Q15: =P15 -> 0
B16: Premises Costs | P16: =+SUM(C16:O16) -> 0 | Q16: =P16 -> 0
B17: Utilities | D17: 5 | E17: 5 | F17: 5 | G17: 5 | H17: 5 | I17: 5 | J17: 5 | K17: 5 | L17: 5 | M17: 5 | N17: 5 | O17: 5 | P17: =+SUM(C17:O17) -> 60 | Q17: =P17 -> 60
B18: Home Working Costs | P18: =+SUM(C18:O18) -> 0 | Q18: =P18 -> 0
B19: Insurances | C19: 12 | D19: 9 | E19: 9 | F19: 9 | G19: 9 | H19: 9 | I19: 9 | J19: 9 | K19: 9 | L19: 9 | M19: 9 | N19: 9 | O19: 9 | P19: =+SUM(C19:O19) -> 120 | Q19: =P19 -> 120
B20: Wages - Staff | P20: =+SUM(C20:O20) -> 0 | Q20: =P20 -> 0
B21: Motor Expenses | D21: 23 | E21: 46 | F21: 23 | G21: 23 | H21: 46 | I21: 23 | J21: 23 | K21: 46 | L21: 23 | M21: 23 | N21: 23 | O21: 46 | P21: =+SUM(C21:O21) -> 368 | Q21: =P21 -> 368
B22: Phone / Internet | P22: =+SUM(C22:O22) -> 0 | Q22: =P22 -> 0
B23: Advertising | D23: 40 | E23: 40 | F23: 40 | G23: 40 | H23: 40 | I23: 40 | J23: 40 | K23: 40 | L23: 40 | M23: 40 | N23: 40 | O23: 40 | P23: =+SUM(C23:O23) -> 480 | Q23: =P23 -> 480
B24: Print / Stationery | D24: 5 | E24: 5 | F24: 5 | G24: 5 | H24: 5 | I24: 5 | J24: 5 | K24: 5 | L24: 5 | M24: 5 | N24: 5 | O24: 5 | P24: =+SUM(C24:O24) -> 60 | Q24: =P24 -> 60
B25: Equipment | P25: =+SUM(C25:O25) -> 0 | Q25: =P25 -> 0
B26: Loan Repayments | D26: 58.71 | E26: 58.71 | F26: 58.71 | G26: 58.71 | H26: 58.71 | I26: 58.71 | J26: 58.71 | K26: 58.71 | L26: 58.71 | M26: 58.71 | N26: 58.71 | O26: 58.71 | P26: =+SUM(C26:O26) -> 704.52 | Q26: =P26 -> 704.52
B27: Bank Charges | P27: =+SUM(C27:O27) -> 0 | Q27: =P27 -> 0
B28: Professional Fees | C28: 100 | D28: 20 | E28: 20 | F28: 20 | G28: 20 | H28: 20 | I28: 20 | J28: 20 | K28: 20 | L28: 20 | M28: 20 | N28: 20 | O28: 20 | P28: =+SUM(C28:O28) -> 340 | Q28: =P28 -> 340
B29: Website | D29: 40 | E29: 40 | F29: 40 | G29: 40 | H29: 40 | I29: 40 | J29: 40 | K29: 40 | L29: 40 | M29: 40 | N29: 40 | O29: 40 | P29: =+SUM(C29:O29) -> 480 | Q29: =P29 -> 480
B30: fragrance oils | C30: 1000 | P30: =+SUM(C30:O30) -> 1000 | Q30: =P30 -> 1000
B31: packaging | C31: 1000 | P31: =+SUM(C31:O31) -> 1000 | Q31: =P31 -> 1000
P32: =+SUM(C32:O32) -> 0 | Q32: =P32 -> 0
B33: VAT | P33: =+SUM(C33:O33) -> 0 | Q33: =P33 -> 0
B34: Drawings/Salary | J34: 850 | K34: 850 | L34: 850 | M34: 850 | N34: 850 | O34: 850 | P34: =+SUM(C34:O34) -> 5100 | Q34: =P34 -> 5100 | R34: This is how much you are paying yourself
B35: NI - Class 4 | P35: =+SUM(C35:O35) -> 0 | Q35: =P35 -> 0 | R35: Will have to pay if profit over £9,500
B36: NI - Class 2 | D36: 13.22 | E36: 13.22 | F36: 13.22 | G36: 13.22 | H36: 13.22 | I36: 13.22 | J36: 13.22 | K36: 13.22 | L36: 13.22 | M36: 13.22 | N36: 13.22 | O36: 13.22 | P36: =+SUM(C36:O36) -> 158.64 | Q36: =P36 -> 158.64
B37: Provision for Tax | P37: =+SUM(C37:O37) -> 0 | Q37: =P37 -> 0 | R37: Will have to pay if profit over £12,000
B38: Total Expenditure | C38: =SUM(C14:C37) -> 2412 | D38: =SUM(D14:D37) -> 836.93 | E38: =SUM(E14:E37) -> 554.08 | F38: =SUM(F14:F37) -> 661.48 | G38: =SUM(G14:G37) -> 687.87 | H38: =SUM(H14:H37) -> 741.84 | I38: =SUM(I14:I37) -> 749.55 | J38: =SUM(J14:J37) -> 1615.63 | ... Q38: =SUM(Q14:Q37) -> 16345.57
B39: Income less Expend | C39: =SUM(C13-C38) -> 88 | D39: =SUM(D13-D38) -> 613.07 | E39: =SUM(E13-E38) -> 163.42 | F39: =SUM(F13-F38) -> 388.52 | G39: =SUM(G13-G38) -> 319.13 | H39: =SUM(H13-H38) -> 363.66 | I39: =SUM(I13-I38) -> 418.95 | J39: =SUM(J13-J38) -> -400.63 | ... Q39: =SUM(Q13-Q38) -> 129.93 | R39: NP (Net Profit)
B40: Opening Bank Balance | C40: 0 | D40: =SUM(C41) -> 88 | E40: =D41 -> 701.07 | F40: =E41 -> 864.49 | G40: =F41 -> 1253.01 | H40: =G41 -> 1572.14 | I40: =H41 -> 1935.8 | J40: =I41 -> 2354.75 | K40: =J41 -> 1954.12 | L40: =K41 -> 1535.07 | ... O40: =N41 -> 468.76 | Q40: =Q36+Q35+Q37+Q34 -> 5258.64 | R40: Draw + Tax
B41: Closing Bank Balance | C41: =SUM(C39+C40) -> 88 | D41: =SUM(D39+D40) -> 701.07 | E41: =SUM(E39+E40) -> 864.49 | F41: =SUM(F39+F40) -> 1253.01 | G41: =SUM(G39+G40) -> 1572.14 | H41: =SUM(H39+H40) -> 1935.8 | I41: =SUM(I39+I40) -> 2354.75 | J41: =SUM(J39+J40) -> 1954.12 | ... O41: =SUM(O39+O40) -> 129.93 | Q41: =SUM(Q39:Q40) -> 5388.57 | R41: Taxable
B43: Personal Expenditure | D43: ='Personal Expenditure'!$I38 -> 839 | E43: ='Personal Expenditure'!$I38 -> 839 | F43: ='Personal Expenditure'!$I38 -> 839 | G43: ='Personal Expenditure'!$I38 -> 839 | H43: ='Personal Expenditure'!$I38 -> 839 | I43: ='Personal Expenditure'!$I38 -> 839 | J43: ='Personal Expenditure'!$I38 -> 839 | K43: ='Personal Expenditure'!$I38 -> 839 | ... O43: ='Personal Expenditure'!$I38 -> 839 | P43: This is how much you need to pay all of your bills (taken from previous page)
B44: Regular Income | D44: ='Personal Expenditure'!$E20 -> 240 | E44: ='Personal Expenditure'!$E20 -> 240 | F44: ='Personal Expenditure'!$E20 -> 240 | G44: ='Personal Expenditure'!$E20 -> 240 | H44: ='Personal Expenditure'!$E20 -> 240 | I44: ='Personal Expenditure'!$E20 -> 240 | J44: ='Personal Expenditure'!$E20 -> 240 | K44: ='Personal Expenditure'!$E20 -> 240 | ... O44: ='Personal Expenditure'!$E20 -> 240
...

Sheet Cash Flow Forecast Yr2
B2: Cash flow Forecast | D2: Name: | F2: ='Personal Expenditure'!D4 -> tracie walker
D4: Business Name: | F4: ='Personal Expenditure'!D6 -> conscious candles n mindful melts
B5: NB: Only required for loans over £2,500
D6: Date: | F6: ='Personal Expenditure'!D8 -> 44520
B8: Year 2 | C8: ='Sales Forecast'!E9 -> Dec | D8: ='Sales Forecast'!F9 -> Jan | E8: ='Sales Forecast'!G9 -> Feb | F8: ='Sales Forecast'!H9 -> Mar | G8: ='Sales Forecast'!I9 -> Apr | H8: ='Sales Forecast'!J9 -> May | I8: ='Sales Forecast'!K9 -> Jun | J8: ='Sales Forecast'!L9 -> Jul | ... N8: ='Sales Forecast'!P9 -> Nov
C9: M 13 | D9: M 14 | E9: M 15 | F9: M 16 | G9: M 17 | H9: M 18 | I9: M 19 | J9: M 20 | K9: M 21 | L9: M 22 | M9: M 23 | N9: M 24 | O9: Totals | P9: P&L
B10: Sales | C10: ='Sales Forecast'!E40 -> 0 | D10: ='Sales Forecast'!F40 -> 0 | E10: ='Sales Forecast'!G40 -> 0 | F10: ='Sales Forecast'!H40 -> 0 | G10: ='Sales Forecast'!I40 -> 0 | H10: ='Sales Forecast'!J40 -> 0 | I10: ='Sales Forecast'!K40 -> 0 | J10: ='Sales Forecast'!L40 -> 0 | ... N10: ='Sales Forecast'!P40 -> 0 | O10: =SUM(C10:N10) -> 0 | P10: =O10 -> 0
B11: Own Cash/Grants | O11: =SUM(C11:N11) -> 0 | P11: =O11 -> 0
B12: Loans | O12: =SUM(C12:N12) -> 0 | P12: =O12 -> 0
B13: Total Income | C13: =SUM(C10:C12) -> 0 | D13: =SUM(D10:D12) -> 0 | E13: =SUM(E10:E12) -> 0 | F13: =SUM(F10:F12) -> 0 | G13: =SUM(G10:G12) -> 0 | H13: =SUM(H10:H12) -> 0 | I13: =SUM(I10:I12) -> 0 | J13: =SUM(J10:J12) -> 0 | ... P13: =SUM(P10:P12) -> 0
B14: Direct Costs | C14: ='Sales Forecast'!E41 -> 0 | D14: ='Sales Forecast'!F41 -> 0 | E14: ='Sales Forecast'!G41 -> 0 | F14: ='Sales Forecast'!H41 -> 0 | G14: ='Sales Forecast'!I41 -> 0 | H14: ='Sales Forecast'!J41 -> 0 | I14: ='Sales Forecast'!K41 -> 0 | J14: ='Sales Forecast'!L41 -> 0 | ... N14: ='Sales Forecast'!P41 -> 0 | O14: =+SUM(C14:N14) -> 0 | P14: =O14 -> 0
B15: Rent & Rates | O15: =+SUM(C15:N15) -> 0 | P15: =O15 -> 0
B16: Premises Costs | O16: =+SUM(C16:N16) -> 0 | P16: =O16 -> 0
B17: Utilities | O17: =+SUM(C17:N17) -> 0 | P17: =O17 -> 0
B18: Home Working Costs | O18: =+SUM(C18:N18) -> 0 | P18: =O18 -> 0
B19: Insurances | O19: =+SUM(C19:N19) -> 0 | P19: =O19 -> 0
B20: Wages - Staff | O20: =+SUM(C20:N20) -> 0 | P20: =O20 -> 0
B21: Motor Expenses | O21: =+SUM(C21:N21) -> 0 | P21: =O21 -> 0
B22: Phone / Internet | O22: =+SUM(C22:N22) -> 0 | P22: =O22 -> 0
B23: Advertising | O23: =+SUM(C23:N23) -> 0 | P23: =O23 -> 0
B24: Print / Stationery | O24: =+SUM(C24:N24) -> 0 | P24: =O24 -> 0
B25: Equipment | O25: =+SUM(C25:N25) -> 0 | P25: =O25 -> 0
B26: Loan Repayments | O26: =+SUM(C26:N26) -> 0 | P26: =O26 -> 0
... B30: Miscellaneous | O30: =+SUM(C30:N30) -> 0 | P30: =O30 -> 0
O31: =+SUM(C31:N31) -> 0 | P31: =O31 -> 0
O32: =+SUM(C32:N32) -> 0 | P32: =O32 -> 0
B33: VAT | O33: =+SUM(C33:N33) -> 0 | P33: =O33 -> 0
B34: Drawings/Salary | C34: =C46 -> -581 | D34: =D46 -> -581 | E34: =E46 -> -581 | F34: =F46 -> -581 | G34: =G46 -> -581 | H34: =H46 -> -581 | I34: =I46 -> -581 | J34: =J46 -> -581 | ... N34: =N46 -> -581 | O34: =+SUM(C34:N34) -> -6972 | P34: =O34 -> -6972
B35: NI - Class 4 | O35: =+SUM(C35:N35) -> 0 | P35: =O35 -> 0
B36: NI - Class 2 | C36: 12.35 | D36: 12.35 | E36: 12.35 | F36: 12.35 | G36: 12.35 | H36: 12.35 | I36: 12.35 | J36: 12.35 | K36: 12.35 | L36: 12.35 | M36: 12.35 | N36: 12.35 | O36: =+SUM(C36:N36) -> 148.2 | P36: =O36 -> 148.2
B37: Provision for Tax | O37: =+SUM(C37:N37) -> 0 | P37: =O37 -> 0
B38: Total Expenditure | C38: =SUM(C14:C37) -> -568.65 | D38: =SUM(D14:D37) -> -568.65 | E38: =SUM(E14:E37) -> -568.65 | F38: =SUM(F14:F37) -> -568.65 | G38: =SUM(G14:G37) -> -568.65 | H38: =SUM(H14:H37) -> -568.65 | I38: =SUM(I14:I37) -> -568.65 | J38: =SUM(J14:J37) -> -568.65 | ... P38: =SUM(P14:P37) -> -6823.8
B39: Income less Expend | C39: =SUM(C13-C38) -> 568.65 | D39: =SUM(D13-D38) -> 568.65 | E39: =SUM(E13-E38) -> 568.65 | F39: =SUM(F13-F38) -> 568.65 | G39: =SUM(G13-G38) -> 568.65 | H39: =SUM(H13-H38) -> 568.65 | I39: =SUM(I13-I38) -> 568.65 | J39: =SUM(J13-J38) -> 568.65 | ... P39: =SUM(P13-P38) -> 6823.8 | Q39: NP (Net Profit)
B40: Opening Bank Balance | C40: 0 | D40: =C41 -> 568.65 | E40: =D41 -> 1137.3 | F40: =E41 -> 1705.95 | G40: =F41 -> 2274.6 | H40: =G41 -> 2843.25 | I40: =H41 -> 3411.9 | J40: =I41 -> 3980.55 | K40: =J41 -> 4549.2 | ... N40: =M41 -> 6255.15 | P40: =P36+P35+P37+P34 -> -6823.8 | Q40: Draw + Tax
B41: Closing Bank Balance | C41: =SUM(C39+C40) -> 568.65 | D41: =SUM(D39+D40) -> 1137.3 | E41: =SUM(E39+E40) -> 1705.95 | F41: =SUM(F39+F40) -> 2274.6 | G41: =SUM(G39+G40) -> 2843.25 | H41: =SUM(H39+H40) -> 3411.9 | I41: =SUM(I39+I40) -> 3980.55 | J41: =SUM(J39+J40) -> 4549.2 | ... N41: =SUM(N39+N40) -> 6823.8 | P41: =SUM(P39:P40) -> 0 | Q41: Taxable
B43: Personal Expenditure | C43: ='Personal Expenditure'!$I38 -> 839 | D43: ='Personal Expenditure'!$I38 -> 839 | E43: ='Personal Expenditure'!$I38 -> 839 | F43: ='Personal Expenditure'!$I38 -> 839 | G43: ='Personal Expenditure'!$I38 -> 839 | H43: ='Personal Expenditure'!$I38 -> 839 | I43: ='Personal Expenditure'!$I38 -> 839 | J43: ='Personal Expenditure'!$I38 -> 839 | ... N43: ='Personal Expenditure'!$I38 -> 839
B44: Regular Income | C44: ='Personal Expenditure'!$E20 -> 240 | D44: ='Personal Expenditure'!$E20 -> 240 | E44: ='Personal Expenditure'!$E20 -> 240 | F44: ='Personal Expenditure'!$E20 -> 240 | G44: ='Personal Expenditure'!$E20 -> 240 | H44: ='Personal Expenditure'!$E20 -> 240 | I44: ='Personal Expenditure'!$E20 -> 240 | J44: ='Personal Expenditure'!$E20 -> 240 | ... N44: ='Personal Expenditure'!$E20 -> 240
B45: Reducing Income | C45: ='Personal Expenditure'!$E25 -> 1180 | D45: ='Personal Expenditure'!$E25 -> 1180 | E45: ='Personal Expenditure'!$E25 -> 1180 | F45: ='Personal Expenditure'!$E25 -> 1180 | G45: ='Personal Expenditure'!$E25 -> 1180 | H45: ='Personal Expenditure'!$E25 -> 1180 | I45: ='Personal Expenditure'!$E25 -> 1180 | J45: ='Personal Expenditure'!$E25 -> 1180 | ... N45: ='Personal Expenditure'!$E25 -> 1180
B46: Drawings required | C46: =SUM(C43-C44-C45) -> -581 | D46: =SUM(D43-D44-D45) -> -581 | E46: =SUM(E43-E44-E45) -> -581 | F46: =SUM(F43-F44-F45) -> -581 | G46: =SUM(G43-G44-G45) -> -581 | H46: =SUM(H43-H44-H45) -> -581 | I46: =SUM(I43-I44-I45) -> -581 | J46: =SUM(J43-J44-J45) -> -581 | ... N46: =SUM(N43-N44-N45) -> -581
